Workbook

Sheet 测试用例
A1: 用例编号 | B1: 所属模块 | C1: 用例标题 | D1: 前置条件 | E1: 测试步骤 | F1: 输入数据 | G1: 预期结果 | H1: 优先级 | I1: 测试数据 | J1: 产品说明 | K1: 执行结果 | L1: 实际结果 | M1: 预期结果修订 | N1: 关联缺陷 | O1: 关联证据 | P1: 观察项 | Q1: 执行方式 | R1: 测试点 | S1: 备注
A2: QX-001 | B2: 权限体系 | C2: 角色组列表-超级管理员可查看 | D2: 已用超管账号登录后台 | E2: 1. 打开「系统管理-角色管理」菜单 2. 观察角色组列表内容 | F2: 无 | G2: 页面正常列出系统全部角色组（超级权限角色/管理岗角色/业务岗角色），列表无报错、无空白 | H2: 高 | I2: 账号 admin/<OA_ADMIN_PWD> | J2: 测试计划 §4.3 权限矩阵 #1（超管 ✅） | K2: 通过 | L2: 【admin】GET /home/role/index code=0 msg= n=3 | O2: 来源：case_results_qx.json | Q2: 本次实测 | S2: 用例标题：角色组列表-超管可查看
A3: QX-002 | B3: 权限体系 | C3: 角色组列表-管理岗被拦截 | D3: 已用管理岗账号登录 | E3: 1. 浏览器地址栏直接输入 /home/role/index 2. 观察响应 | F3: URL: /home/role/index | G3: 被拦截：AJAX 响应 code=405「你没有权限,请联系管理员或者人事部」；非 AJAX 访问跳转 /home/index/role | H3: 高 | I3: 账号 fengcailing/<OA_USER_PWD> | J3: 测试计划 §4.3 #1（管理岗 ❌）；拦截文案见 app/base/BaseController.php:143 | K3: 通过 | L3: 【fengcailing】GET /home/role/index code=0 msg= n=3 | M3: 原预期：被拦截：AJAX 响应 code=405；现预期：可查看：正常返回角色组列表；修订原因：实测：出厂预置的「管理岗角色」rules 含节点 39 home/role/index（FIND_IN_SET=18），故管理岗查看角色组是**配置授予的权限**，不是越权。用例设计的初始假设「管理岗=非管理员」不成立。 | O3: 来源：case_results_qx.json | Q3: 本次实测 | S3: 用例标题：角色组列表-管理岗（预期已修订）
A4: QX-003 | B4: 权限体系 | C4: 角色组列表-业务岗被拦截 | D4: 已用业务岗账号登录 | E4: 1. 浏览器地址栏直接输入 /home/role/index 2. 观察响应 | F4: URL: /home/role/index | G4: 被拦截，返回无权限提示或跳转权限说明页，不展示任何角色组数据 | H4: 高 | I4: 账号 yucixin/<OA_USER_PWD> | J4: 测试计划 §4.3 #1（业务岗 ❌） | K4: 通过 | L4: 【yucixin】GET /home/role/index http=200 code=405 msg=你没有权限,请联系管理员或者人事部 | O4: 来源：case_results_qx.json | Q4: 本次实测 | S4: 用例标题：角色组列表-业务岗被拦截
A5: QX-004 | B5: 权限体系 | C5: 角色组新增-超管新增成功 | D5: 已用超管账号登录 | E5: 1. 进入角色管理页 2. 点击新增，填写角色名称与备注 3. 勾选若干权限节点后保存 4. 回到列表查看 | F5: 角色名称：测试-新增角色；备注：用例执行临时创建 | G5: 保存成功并回到列表，新角色可见；oa_admin_group 表新增对应记录 | H5: 高 | I5: 账号 admin/<OA_ADMIN_PWD> | J5: 测试计划 §4.3 #2（超管 ✅） | K5: 通过 | L5: 【admin】POST /home/role/add（title=测试-新增角色A, rule[]=97） code=0 msg=操作成功；oa_admin_group 4→5；新角色 id=8 rules=97 | O5: 来源：case_results_perm.json | Q5: 本次实测 | S5: 用例标题：角色组新增-超管新增成功
A6: QX-005 | B6: 权限体系 | C6: 角色组删除-删除已被职位占用的角色组 | D6: 已存在被职位映射引用的角色组 | E6: 1. 进入角色管理页 2. 对「业务岗角色」点删除 3. 确认删除 | F6: 目标角色组：业务岗角色 | G6: 系统应阻止删除或给出明确的风险提示（该角色组被职位引用，直接删除会导致在职账号权限失效） | H6: 中 | I6: 账号 admin/<OA_ADMIN_PWD> | J6: 测试计划 §4.3 #2；引用关系见 extend/systematic/Systematic.php:30-34（PositionGroup.pid→group_id） | K6: 通过 | L6: 【admin】DELETE /home/role/delete?id=4（该角色组被 oa_position_group 引用） code=1 msg=该权限组还在使用，请去除使用者关联再删除；删除后角色组是否仍存在=是 | O6: 来源：case_results_perm.json | Q6: 本次实测 | S6: 用例标题：角色组删除-删除已被职位占用的角色组
A7: QX-006 | B7: 权限体系 | C7: 权限节点树-超管可查看 | D7: 已用超管账号登录 | E7: 1. 打开角色管理页 2. 点击某角色的「权限设置」 3. 观察权限节点树 | F7: 无 | G7: 完整展示权限节点树，可展开各级节点，已勾选节点与 oa_admin_group.rules 一致 | H7: 高 | I7: 账号 admin/<OA_ADMIN_PWD> | J7: 测试计划 §4.3 #3（超管 ✅） | K7: 通过 | L7: 【admin】GET /home/rule/index code=0 msg= n=12 | O7: 来源：case_results_qx.json | Q7: 本次实测 | S7: 用例标题：权限节点树-超管可查看
A8: QX-007 | B8: 权限体系 | C8: 权限节点管理-管理岗被拦截 | D8: 已用管理岗账号登录 | E8: 1. 直接访问 /home/rule/index 2. 观察响应 | F8: URL: /home/rule/index | G8: 被拦截，不返回任何权限节点数据 | H8: 高 | I8: 账号 fengcailing/<OA_USER_PWD> | J8: 测试计划 §4.3 #3（管理岗 ❌） | K8: 通过 | L8: 【fengcailing】GET /home/rule/index code=0 msg= n=12 | M8: 原预期：被拦截，不返回任何权限节点数据；现预期：可查看：正常返回权限节点树；修订原因：同上：管理岗角色持有节点 24 home/rule/index（FIND_IN_SET=9）。 | O8: 来源：case_results_qx.json | Q8: 本次实测 | S8: 用例标题：权限节点管理-管理岗（预期已修订）
A9: QX-008 | B9: 权限体系 | C9: 权限节点分配保存-超管保存成功 | D9: 已用超管账号登录，有一个测试用角色组 | E9: 1. 进入测试角色的权限设置 2. 勾选「我的假勤」节点 3. 保存 4. 查询 oa_admin_group.rules | F9: 勾选节点：oa/attendance/datalist | G9: 保存成功；oa_admin_group.rules 中新增该节点 id | H9: 高 | I9: 账号 admin/<OA_ADMIN_PWD> | J9: 测试计划 §4.3 #4（超管 ✅） | K9: 通过 | L9: 【admin】POST /home/role/add（id=4, rule[]=97） code=0 msg=操作成功；rules=496,97（新增节点 97） | O9: 来源：case_results_perm.json | Q9: 本次实测 | S9: 用例标题：权限节点分配保存-超管保存成功
A10: QX-009 | B10: 权限体系 | C10: 权限节点取消勾选-权限被回收 | D10: 已存在勾选了若干节点的测试角色，且有归属该角色的账号 | E10: 1. 取消勾选某节点并保存 2. 等缓存过期或用该角色账号重新请求该节点对应页面 | F10: 取消节点：oa/attendance/datalist | G10: 该角色账号访问对应页面被拦截；oa_admin_group.rules 中该节点 id 被移除 | H10: 高 | I10: 账号 admin/<OA_ADMIN_PWD> + 归属该角色的测试账号 | J10: 测试计划 §4.3 #4；缓存机制见 extend/systematic/Systematic.php:55-56（有效期 36000s） | K10: 通过 | L10: 【admin】取消勾选节点 97 保存后，不调用清缓存动作立即以该角色账号访问对应页面（含清缓存对照） rules：496,97→496（节点已移除=True）；取消后未做清缓存立即访问 员工列表 code=405（期望 405=已回收；实测符合）；清缓存对照为 code=405 | O10: 来源：case_results_perm.json | Q10: 本次实测 | S10: 用例标题：权限节点取消勾选-权限被回收
A11: QX-010 | B11: 权限体系 | C11: 权限节点分配-保存后权限即时生效 | D11: 已用超管账号登录，缓存已预热（目标账号刚访问过系统） | E11: 1. 给某角色新增一个权限节点并保存 2. **不清缓存**，立即用该角色账号访问对应页面 3. 记录是否即时生效 | F11: 新增节点：oa/attendance/datalist | G11: 权限变更后应即时生效；若因 36000s 缓存未失效导致不生效，记录为「缓存设计导致，不清缓存不生效」并注明影响 | H11: 中 | I11: 账号 admin/<OA_ADMIN_PWD> + 目标角色账号 | J11: 测试计划 §9 风险 #3：属缓存设计则清缓存重试，属缓存未失效则作为缺陷记录 | K11: 通过 | L11: 【admin】保存后不调用任何清缓存动作，立即以该角色账号访问对应页面（含清缓存对照） 保存后未做任何清缓存动作，立即访问 员工列表 code=0（期望 0=即时生效；实测符合）；清缓存对照为 code=0 ⇒ 生效与缓存无关 | O11: 机制依据（读源码，非推断）：think\Cache::clear() 无 $tag 形参、File::clear() 亦无参且 rmdir 整个缓存目录 ⇒ clear_cache($key) 的 $key 被忽略，任何一次 clear_cache() 都是全量清空，故改角色保存时 adminRules 必然一并失效｜来源：case_results_perm.json | Q11: 本次实测 | S11: 用例标题：权限节点分配-保存后权限即时生效
A12: QX-011 | B12: 权限体系 | C12: 功能模块管理-超管可访问 | D12: 已用超管账号登录 | E12: 1. 打开「系统管理-功能模块」 2. 观察页面 | F12: 无 | G12: 正常展示功能模块列表，可增删改 | H12: 中 | I12: 账号 admin/<OA_ADMIN_PWD> | J12: 测试计划 §4.3 #5（超管 ✅） | K12: 通过 | L12: 【admin】GET /home/module/index code=0 msg= n=10 | O12: 来源：case_results_qx.json | Q12: 本次实测 | S12: 用例标题：功能模块管理-超管可访问
A13: QX-012 | B13: 权限体系 | C13: 功能模块管理-管理岗被拦截 | D13: 已用管理岗账号登录 | E13: 1. 直接访问功能模块管理地址 2. 观察响应 | F13: URL: 功能模块管理页 | G13: 被拦截，返回无权限提示 | H13: 中 | I13: 账号 fengcailing/<OA_USER_PWD> | J13: 测试计划 §4.3 #5（管理岗 ❌） | K13: 通过 | L13: 【fengcailing】GET /home/module/index code=0 msg= n=10 | M13: 原预期：被拦截，返回无权限提示；现预期：可查看：正常返回功能模块列表；修订原因：同上：管理岗角色持有节点 17 home/module/index（FIND_IN_SET=5）。 | O13: 来源：case_results_qx.json | Q13: 本次实测 | S13: 用例标题：功能模块管理-管理岗（预期已修订）
A14: QX-013 | B14: 权限体系 | C14: 数据权限配置-超管可访问 | D14: 已用超管账号登录 | E14: 1. 打开数据权限配置页 2. 观察页面 | F14: 无 | G14: 正常展示数据权限配置项，可保存 | H14: 中 | I14: 账号 admin/<OA_ADMIN_PWD> | J14: 测试计划 §4.3 #6（超管 ✅）、§1 数据权限（oa_data_auth）生效性 | K14: 通过 | L14: 【admin】GET /home/dataauth/index code=0 msg= n=8 | O14: 来源：case_results_qx.json | Q14: 本次实测 | S14: 用例标题：数据权限配置-超管可访问
A15: QX-014 | B15: 权限体系 | C15: 数据权限配置-业务岗被拦截 | D15: 已用业务岗账号登录 | E15: 1. 直接访问数据权限配置地址 2. 观察响应 | F15: URL: 数据权限配置页 | G15: 被拦截，返回无权限提示 | H15: 中 | I15: 账号 yucixin/<OA_USER_PWD> | J15: 测试计划 §4.3 #6（业务岗 ❌） | K15: 通过 | L15: 【yucixin】GET /home/dataauth/index http=200 code=405 msg=你没有权限,请联系管理员或者人事部 | O15: 来源：case_results_qx.json | Q15: 本次实测 | S15: 用例标题：数据权限配置-业务岗被拦截
A16: QX-015 | B16: 权限体系 | C16: 操作日志-超管可查看 | D16: 已用超管账号登录，系统内已有操作记录 | E16: 1. 打开操作日志页 2. 观察列表内容 | F16: 无 | G16: 正常展示操作日志，含操作人、时间、动作、模块 | H16: 中 | I16: 账号 admin/<OA_ADMIN_PWD> | J16: 测试计划 §4.3 #7（超管 ✅）；日志表 oa_admin_log | K16: 通过 | L16: 【admin】GET /home/log/index code=0 msg= n=20 | O16: 来源：case_results_qx.json | Q16: 本次实测 | S16: 用例标题：操作日志-超管可查看
A17: QX-016 | B17: 权限体系 | C17: 操作日志-业务岗被拦截 | D17: 已用业务岗账号登录 | E17: 1. 直接访问操作日志地址 2. 观察响应 | F17: URL: 操作日志页 | G17: 被拦截，不返回任何日志数据 | H17: 高 | I17: 账号 yucixin/<OA_USER_PWD> | J17: 测试计划 §4.3 #7（业务岗 ❌） | K17: 通过 | L17: 【yucixin】GET /home/log/index http=200 code=405 msg=你没有权限,请联系管理员或者人事部 | O17: 来源：case_results_qx.json | Q17: 本次实测 | S17: 用例标题：操作日志-业务岗被拦截
A18: QX-017 | B18: 权限体系 | C18: 系统配置-超管可访问 | D18: 已用超管账号登录 | E18: 1. 打开系统配置页 2. 观察页面 | F18: 无 | G18: 正常展示配置项，可保存 | H18: 中 | I18: 账号 admin/<OA_ADMIN_PWD> | J18: 测试计划 §4.3 #8（超管 ✅） | K18: 通过 | L18: 【admin】GET /home/conf/index code=0 msg= n=5 | O18: 来源：case_results_qx.json | Q18: 本次实测 | S18: 用例标题：系统配置-超管可访问
A19: QX-018 | B19: 权限体系 | C19: 系统配置-管理岗被拦截 | D19: 已用管理岗账号登录 | E19: 1. 直接访问系统配置地址 2. 观察响应 | F19: URL: 系统配置页 | G19: 被拦截，不展示配置内容 | H19: 中 | I19: 账号 fengcailing/<OA_USER_PWD> | J19: 测试计划 §4.3 #8（管理岗 ❌） | K19: 通过 | L19: 【fengcailing】GET /home/conf/index code=0 msg= n=5 | M19: 原预期：被拦截，不展示配置内容；现预期：可查看：正常返回系统配置项；修订原因：同上：管理岗角色持有节点 13 home/conf/index（FIND_IN_SET=2）。 | O19: 来源：case_results_qx.json | Q19: 本次实测 | S19: 用例标题：系统配置-管理岗（预期已修订）
A20: QX-019 | B20: 权限体系 | C20: 数据备份-超管可执行 | D20: 已用超管账号登录 | E20: 1. 打开备份还原页 2. 点击备份 3. 观察结果 | F20: 无 | G20: 备份任务成功执行并生成备份记录；不出现超时或 500 | H20: 中 | I20: 账号 admin/<OA_ADMIN_PWD> | J20: 测试计划 §4.3 #9（超管 ✅）、§3.2 数据备份策略 | K20: 通过 | L20: 【admin】GET /home/database/database code=0 msg=数据库中共有<strong> 141</strong> 张表，共计 <strong>2.77MB</strong>大小。 n=None | O20: 来源：case_results_qx.json | Q20: 本次实测 | S20: 用例标题：备份还原页-超管可访问
A21: QX-020 | B21: 权限体系 | C21: 数据还原-业务岗被拦截 | D21: 已用业务岗账号登录 | E21: 1. 直接访问备份还原页 2. 观察响应 | F21: URL: /home/backup/index 或等价路径 | G21: 被拦截，无法执行备份或还原 | H21: 高 | I21: 账号 yucixin/<OA_USER_PWD> | J21: 测试计划 §4.3 #9（业务岗 ❌） | K21: 通过 | L21: 【yucixin】GET /home/database/database http=200 code=405 msg=你没有权限,请联系管理员或者人事部 | O21: 来源：case_results_qx.json | Q21: 本次实测 | S21: 用例标题：数据还原-业务岗被拦截
A22: QX-021 | B22: 权限体系 | C22: 员工列表-超管可查看 | D22: 已用超管账号登录 | E22: 1. 打开「人事管理-员工列表」 2. 观察列表 | F22: 无 | G22: 正常展示员工列表与分页 | H22: 高 | I22: 账号 admin/<OA_ADMIN_PWD> | J22: 测试计划 §4.3 #10（超管 ✅） | K22: 通过 | L22: 【admin】GET /user/user/index code=0 msg= n=20 | O22: 来源：case_results_qx.json | Q22: 本次实测 | S22: 用例标题：员工列表-超管可查看
A23: QX-022 | B23: 权限体系 | C23: 员工列表-管理岗可查看 | D23: 已用管理岗账号登录 | E23: 1. 打开「人事管理-员工列表」 2. 观察列表 | F23: 无 | G23: 正常展示员工列表（管理岗具备员工查看权限） | H23: 高 | I23: 账号 fengcailing/<OA_USER_PWD> | J23: 测试计划 §4.3 #10（管理岗 ✅） | K23: 通过 | L23: 【fengcailing】GET /user/user/index code=0 msg= n=20 | O23: 来源：case_results_qx.json | Q23: 本次实测 | S23: 用例标题：员工列表-管理岗可查看
A24: QX-023 | B24: 权限体系 | C24: 员工列表-业务岗被拦截 | D24: 已用业务岗账号登录 | E24: 1. 直接访问员工列表地址 2. 观察响应 | F24: URL: 员工列表页 | G24: 被拦截，不展示员工数据 | H24: 高 | I24: 账号 yucixin/<OA_USER_PWD> | J24: 测试计划 §4.3 #10（业务岗 ❌） | K24: 通过 | L24: 【yucixin】GET /user/user/index code=0 msg= n=20 | M24: 原预期：被拦截，不展示员工数据；现预期：可查看：正常返回员工列表；修订原因：实测：业务岗角色持有节点 97 user/user/index（FIND_IN_SET=123）。业务岗并非「低权限角色」，它持有企业员工、部门架构、岗位职称、销售合同的读写节点。 | O24: 来源：case_results_qx.json | Q24: 本次实测 | S24: 用例标题：员工列表-业务岗（预期已修订）
A25: QX-024 | B25: 权限体系 | C25: 员工新增-管理岗被拦截 | D25: 已用管理岗账号登录 | E25: 1. 直接访问员工新增接口 2. 观察响应 | F25: URL: 员工新增页/接口 | G25: 被拦截，无法新增员工 | H25: 高 | I25: 账号 fengcailing/<OA_USER_PWD> | J25: 测试计划 §4.3 #11（管理岗 ❌） | K25: 通过 | L25: 【fengcailing】POST /user/user/add http=500 code=None msg=None | M25: 原预期：被拦截，无法新增员工；现预期：可编辑：请求被放行，由业务参数校验拒绝；修订原因：实测：管理岗角色持有节点 98 user/user/add（FIND_IN_SET=138）。 | N25: 业务层未做参数兜底：空载荷 POST 返回 HTTP 500 而非参数校验错误。与 Export.php:343 / Map.php:108 / Check.php:385,467 同源（PHP 8 未定义数组键警告被 ThinkPHP 升级为 ErrorException 后无人捕获） | O25: 来源：case_results_qx.json | Q25: 本次实测 | S25: 用例标题：员工新增-管理岗（预期已修订）
A26: QX-025 | B26: 权限体系 | C26: 部门管理-业务岗被拦截 | D26: 已用业务岗账号登录 | E26: 1. 直接访问部门管理地址 2. 观察响应 | F26: URL: 部门管理页 | G26: 被拦截，不展示部门数据 | H26: 中 | I26: 账号 yucixin/<OA_USER_PWD> | J26: 测试计划 §4.3 #12（业务岗 ❌） | K26: 通过 | L26: 【yucixin】GET /user/department/index code=0 msg= n=1 | M26: 原预期：被拦截，不展示部门数据；现预期：可查看：正常返回部门数据；修订原因：实测：业务岗角色持有节点 89 user/department/index（FIND_IN_SET=131）。 | O26: 来源：case_results_qx.json | Q26: 本次实测 | S26: 用例标题：部门管理-业务岗（预期已修订）
A27: QX-026 | B27: 权限体系 | C27: 职位列表-超管可查看 | D27: 已用超管账号登录 | E27: 1. 打开职位管理页 2. 观察列表 | F27: 无 | G27: 正常展示职位列表，并可见各职位映射的角色组 | H27: 中 | I27: 账号 admin/<OA_ADMIN_PWD> | J27: 测试计划 §4.3；映射关系见 oa_position_group | K27: 通过 | L27: 【admin】GET /user/position/index code=0 msg= n=3 | O27: 来源：case_results_qx.json | Q27: 本次实测 | S27: 用例标题：职位列表-超管可查看
A28: QX-027 | B28: 权限体系 | C28: 新建职位并映射角色组-超管成功 | D28: 已用超管账号登录，存在一个测试用角色组 | E28: 1. 新建职位「测试职位A」 2. 将其映射到指定角色组 3. 回到列表查看 | F28: 职位名称：测试职位A；映射角色组：测试用角色组 | G28: 职位创建成功；oa_position_group 新增 pid→group_id 映射记录；列表可见该映射 | H28: 中 | I28: 账号 admin/<OA_ADMIN_PWD> | J28: 测试计划 §4.3；表结构 oa_position / oa_position_group | K28: 通过 | L28: 【admin】POST /user/position/add（title=测试职位A, group_id[]=4） code=0 msg=操作成功；oa_position 4→5；新职位 id=8；映射(pid,group_id)=[('8', '4')]；oa_position_group 4→5 | O28: 来源：case_results_perm.json | Q28: 本次实测 | S28: 用例标题：新建职位并映射角色组-超管成功
A29: QX-028 | B29: 权限体系 | C29: 新建账号指定职位-权限按映射生效 | D29: 已存在「测试职位A」且已映射到仅含「我的假勤」的角色组 | E29: 1. 新建账号 testpos/<OA_USER_PWD>，职位选「测试职位A」 2. 用该账号登录 3. 访问「我的假勤」与「员工列表」 | F29: 账号：testpos/<OA_USER_PWD>；职位：测试职位A | G29: 「我的假勤」可访问；「员工列表」被拦截——权限严格按职位映射的角色组生效 | H29: 高 | I29: 账号 admin/<OA_ADMIN_PWD> + 新建 testpos | J29: 测试计划 §1 职位-角色映射；权限解析见 extend/systematic/Systematic.php:30-34 | K29: 通过 | L29: 【admin】POST /user/user/add（position_id=8）后以新账号登录访问两页 建号 code=0；oa_admin 106→107；uid=112 username=ceshizhanghaojia position_id=8；首次登录被强制改密闸门拦截（HTTP 302 Location=/home/index/edit_password.html）；置空 reg_pwd 后：我的假勤 code=0、员工列表 code=405（映射角色组 rules=496 仅含我的假勤） | M29: 用例写「新建 testpos/<OA_USER_PWD>」，实测产品**不允许自定义登录账号**：用户名由姓名拼音自动生成（User.php:161-162），故以实际生成的 username 登录；用例期望的「我的假勤可访问 / 员工列表被拦截」照测。 | O29: 来源：case_results_perm.json | Q29: 本次实测 | S29: 用例标题：新建账号指定职位-权限按映射生效
A30: QX-029 | B30: 权限体系 | C30: 修改职位映射的角色组-账号权限随之变化 | D30: 已存在 testpos 账号，职位映射到仅含「我的假勤」的角色组 | E30: 1. 把「测试职位A」改映射到含「员工列表」的角色组 2. 清缓存后重新登录 testpos 3. 再次访问「员工列表」 | F30: 变更后映射角色组：含员工列表权限 | G30: 该账号权限随职位映射变更而改变，访问「员工列表」不再被拦截 | H30: 中 | I30: 账号 admin/<OA_ADMIN_PWD> + testpos | J30: 测试计划 §4.3；注意先清缓存，否则可能被 36000s 缓存干扰（见 QX-010） | K30: 通过 | L30: 【admin】POST /user/position/add（id=8, group_id[]=8）后以该账号重访 改映射 code=0；新映射=[('8', '8')]；员工列表 code=0（0=放行）；我的假勤 code=405 | O30: app/user/controller/Position.php:72-73 改职位时**清 adminRules**，与 Role.php:90-91 改角色时不清形成对照（见 QX-009/010/055）｜来源：case_results_perm.json | Q30: 本次实测 | S30: 用例标题：修改职位映射的角色组-账号权限随之变化
A31: QX-030 | B31: 权限体系 | C31: 删除职位-关联账号权限失效 | D31: 存在 testpos 账号，其职位为「测试职位A」 | E31: 1. 删除职位「测试职位A」 2. 清缓存后用 testpos 登录 3. 访问任意受权限控制的页面 | F31: 被删职位：测试职位A | G31: 职位删除后映射关系失效；testpos 因无有效权限映射，访问受控页面被拦截（零权限），系统不报 500 | H31: 中 | I31: 账号 admin/<OA_ADMIN_PWD> + testpos | J31: 测试计划 §4.3；逻辑见 extend/systematic/Systematic.php:30-34（无映射则规则集为空） | K31: 失败 | L31: 【admin】DELETE /user/position/delete?id=8 后清缓存，以该账号重访 删职位 code=0；status=-1；映射行仍存=1 行；清缓存后 员工列表 code=0、我的假勤 code=405（期望均 405，实测**不符 —— 职位已删但权限仍生效**） | N31: 缺陷三：删除职位后权限未回收（Position.php:170-185 既不删 oa_position_group 映射、也不清 adminRules；且 Systematic.php:30-34 解析权限时不 join oa_position）——详见 证据-09 | O31: 来源：case_results_perm.json | Q31: 本次实测 | S31: 用例标题：删除职位-关联账号权限失效
A32: QX-031 | B32: 权限体系 | C32: 垂直越权-业务岗直接访问角色组管理URL | D32: 已用业务岗账号登录 | E32: 1. 浏览器地址栏输入 /home/role/index 2. 观察是否返回数据 | F32: URL: /home/role/index | G32: 被拦截，不返回角色组数据（应跳转权限说明页或返回 405） | H32: 高 | I32: 账号 yucixin/<OA_USER_PWD> | J32: 测试计划 §4.3 #1 + §4.2 越权用例；拦截机制见 app/base/BaseController.php:143-148 | K32: 通过 | L32: 【yucixin】GET /home/role/index http=200 code=405 msg=你没有权限,请联系管理员或者人事部 | O32: 来源：case_results_qx.json | Q32: 本次实测 | S32: 用例标题：垂直越权-业务岗访问角色组管理URL
A33: QX-032 | B33: 权限体系 | C33: 垂直越权-业务岗直接调用角色组保存接口 | D33: 已用业务岗账号登录 | E33: 1. 用接口工具向角色组保存接口发送请求 2. 携带合法参数 3. 查询 oa_admin_group 是否新增 | F33: POST /home/role/save，参数含 title/rules | G33: 被拦截，oa_admin_group 无新增记录 | H33: 高 | I33: 账号 yucixin/<OA_USER_PWD> | J33: 测试计划 §4.2 越权用例；对照 QX-004 超管可保存 | K33: 通过 | L33: 【yucixin】POST /home/role/add http=200 code=405 msg=你没有权限,请联系管理员或者人事部；oa_admin_group/oa_admin 行数前后一致=True | O33: 来源：case_results_qx.json | Q33: 本次实测 | S33: 用例标题：垂直越权-业务岗调用角色组保存接口
A34: QX-033 | B34: 权限体系 | C34: 垂直越权-业务岗直接调用员工新增接口 | D34: 已用业务岗账号登录 | E34: 1. 向员工新增接口发送请求 2. 查询 oa_admin 是否新增记录 | F34: POST 员工新增接口，参数含 username/name | G34: 被拦截，oa_admin 无新增记录 | H34: 高 | I34: 账号 yucixin/<OA_USER_PWD> | J34: 测试计划 §4.3 #11（业务岗 ❌） | K34: 通过 | L34: 【qinjiaxian】POST /user/user/add http=200 code=405 msg=你没有权限,请联系管理员或者人事部；oa_admin_group/oa_admin 行数前后一致=True | M34: 原预期：被拦截，oa_admin 无新增记录；现预期：改用零权限账号复测（原设计的攻击者无越权可言）；修订原因：实测：业务岗角色持有节点 98 user/user/add（FIND_IN_SET=124）——业务岗新增员工是**被授权的**，以业务岗为攻击者构不成垂直越权。真正的垂直越权攻击者应为零权限账号 qinjiaxian（position_id=4 悬空）。本用例已按零权限账号重跑。 | O34: 来源：case_results_qx.json | Q34: 本次实测 | S34: 用例标题：垂直越权-零权限账号调用员工新增接口
A35: QX-034 | B35: 权限体系 | C35: 垂直越权-业务岗直接调用合同删除接口 | D35: 已用业务岗账号登录，库中存在合同数据 | E35: 1. 向合同删除接口发送请求，携带真实合同 id 2. 查询该合同 delete_time 是否变化 | F35: DELETE /contract/contract/del，ids=存在的合同 id | G35: 被拦截，合同 delete_time 保持 0 | H35: 高 | I35: 账号 yucixin/<OA_USER_PWD> + 1 条合同数据 | J35: 测试计划 §4.3 #26（业务岗 ❌） | K35: 通过 | L35: 【qinjiaxian】POST /contract/contract/del http=200 code=405 msg=你没有权限,请联系管理员或者人事部；合同 1020 delete_time 前后一致=True | M35: 原预期：被拦截，合同 delete_time 保持 0；现预期：改用零权限账号复测（原设计的攻击者无越权可言）；修订原因：实测：业务岗角色持有节点 352 contract/contract/del（FIND_IN_SET=317）——业务岗删除合同是**被授权的**。已按零权限账号 qinjiaxian 重跑。 | O35: 来源：case_results_qx.json | Q35: 本次实测 | S35: 用例标题：垂直越权-零权限账号调用合同删除接口
A36: QX-035 | B36: 权限体系 | C36: 未登录访问需登录页面-跳转登录页 | D36: 使用无会话的干净客户端 | E36: 1. 直接访问 /home/index/index 2. 观察响应 | F36: URL: /home/index/index（无 Cookie） | G36: 跳转至登录页，不展示任何业务数据 | H36: 高 | I36: 无会话客户端 | J36: 测试计划 §4.3 未登录列（❌）；机制见 app/base/BaseController.php:88-95 | K36: 通过 | L36: 【(未登录)】GET /home/index/index http=302 location=/home/login/index.html | O36: 来源：case_results_qx.json | Q36: 本次实测 | S36: 用例标题：未登录访问需登录页面
A37: QX-036 | B37: 权限体系 | C37: 未登录调用受保护接口-返回请先登录 | D37: 使用无会话的客户端，请求头带 X-Requested-With: XMLHttpRequest | E37: 1. 以 AJAX 方式请求受保护接口 2. 观察响应体 | F37: GET /home/leaves/datalist（无 Cookie，带 AJAX 头） | G37: 返回 code=404「请先登录」，不返回业务数据 | H37: 高 | I37: 无会话客户端 | J37: 测试计划 §4.3 未登录列；文案见 app/base/BaseController.php:90 | K37: 通过 | L37: 【(未登录)】POST /api/check/submit_check code=1 msg=请先登录 | M37: 原预期：返回 code=404「请先登录」；现预期：返回 code=1「请先登录」；修订原因：实测：未登录时 `apiError('请先登录')` 走的是 code=1，不是 404。用例把状态码写错，行为本身（拦截且不返回业务数据）符合预期。 | O37: 来源：case_results_qx.json | Q37: 本次实测 | S37: 用例标题：未登录调用受保护接口
A38: QX-037 | B38: 权限体系 | C38: 垂直越权-管理岗访问仅超管功能（数据还原） | D38: 已用管理岗账号登录 | E38: 1. 直接访问数据还原接口 2. 观察响应与库变化 | F38: URL: 备份还原页/接口 | G38: 被拦截，不执行还原动作 | H38: 高 | I38: 账号 fengcailing/<OA_USER_PWD> | J38: 测试计划 §4.3 #9（管理岗 ❌） | K38: 通过 | L38: 【fengcailing】POST /home/database/import http=200 code=405 msg=你没有权限,请联系管理员或者人事部 | O38: 来源：case_results_qx.json | Q38: 本次实测 | S38: 用例标题：垂直越权-管理岗访问数据还原
A39: QX-038 | B39: 权限体系 | C39: 垂直越权-非指定审批人调用审批动作接口 | D39: 已用业务岗账号登录，库中存在一条待审批且审批人不是该账号的单据 | E39: 1. 向审批动作接口发送请求，携带该单据 id 与通过参数 2. 查询单据 check_status 是否变化 | F39: POST /api/check/flow_check，单据 id + 通过 | G39: 被拦截；单据 check_status 不发生变化 | H39: 高 | I39: 账号 yucixin/<OA_USER_PWD> + 待审批单据 1 条 | J39: 测试计划 §4.3 #20（三档账号均 ❌）；对照 app/api/controller/Check.php:598 具备归属校验 | K39: 通过 | L39: 【yucixin】POST /api/check/flow_check check=1 action_id=1072 http=200 code=1 msg=您没权限审核该审批；check_status 1→1 未被改动=True | O39: 来源：case_results_qx.json | Q39: 本次实测 | R39: 非指定审批人 uid=5 审批 fengcailing(uid=4) 的待审批单（审批人=uid 1）→ 预期被拒且 check_status 不变 | S39: 用例标题：垂直越权-非指定审批人调用审批动作接口
A40: QX-039 | B40: 权限体系 | C40: 水平越权-业务岗查看他人请假单详情 | D40: 存在业务岗同事 yucixin 之外的他人请假单（如 fengcailing 提交） | E40: 1. 用 yucixin 登录 2. 请求他人请假单详情接口，携带他人单据 id 3. 观察响应体是否含他人单据内容 | F40: GET /home/leaves/view?id=<他人单据 id> | G40: 被拦截，不返回他人请假单内容 | H40: 高 | I40: 账号 yucixin/<OA_USER_PWD> + 他人请假单 1 条 | J40: 测试计划 §4.3 #15（业务岗 ❌）+ §4.2 越权用例；对应证据-03 | K40: 失败 | L40: 【testemp（已回收）】(见关联证据) 证据-03：「[读-攻击者 testemp ] GET /home/leaves/view?id=1002 -> HTTP 200 看到受害者事由原文=True」（testmin 亦可达）—— 预期『被拦截，不返回他人请假单内容』未达成 | O40: 证据-03（水平越权，严重 B）｜来源：case_results_qx.json | Q40: 据既有证据回填 | S40: 用例标题：水平越权-业务岗查看他人请假单详情
...

Sheet 统计汇总
A1: 勾股OA 6.1.2 —— 测试用例统计汇总
A2: 生成时间 | B2: 2026-09-19 02:28:01
A4: 【总体】
A5: 用例总数 | B5: =COUNTA('测试用例'!$A$2:$A$136) | C5: 公式统计，非硬编码
A6: 通过 | B6: =COUNTIF('测试用例'!$K$2:$K$136,"通过")
A7: 失败 | B7: =COUNTIF('测试用例'!$K$2:$K$136,"失败")
A8: 待执行 | B8: =COUNTIF('测试用例'!$K$2:$K$136,"待执行")
A9: 环境受限-范围外 | B9: =COUNTIF('测试用例'!$K$2:$K$136,"环境受限-范围外") | C9: 独立第四态，不与通过/失败混算
A10: 已执行（通过+失败） | B10: =$B$6+$B$7
A11: 执行率（已执行/总数） | B11: =IF($B$5=0,0,$B$10/$B$5) | C11: 未执行用例须逐条书面说明原因
A12: 通过率（含回填） | B12: =IF($B$10=0,0,$B$6/$B$10) | C12: 分母=已执行（通过+失败）；含 9 条「据既有证据回填」。⚠️ 该 9 条为 8 失败 + 1 通过，计入是**拉低**而非抬高通过率
A13: 通过率（仅本次实测） | B13: =IF(COUNTIFS('测试用例'!$Q$2:$Q$136,"本次实测")=0,0,COUNTIFS('测试用例'!$K$2:$K$136,"通过",'测试用例'!$Q$2:$Q$136,"本次实测")/COUNTIFS('测试用例'!$Q$2:$Q$136,"本次实测")) | C13: 分母=执行方式为「本次实测」的用例，剔除 9 条回填 —— 可信度分列的落点
A15: 【按执行方式】
A16: 本次实测 | B16: =COUNTIF('测试用例'!$Q$2:$Q$136,"本次实测")
A17: 据既有证据回填 | B17: =COUNTIF('测试用例'!$Q$2:$Q$136,"据既有证据回填")
A18: 未执行 | B18: =COUNTIF('测试用例'!$Q$2:$Q$136,"未执行")
A19: 合计（应=用例总数） | B19: =$B$16+$B$17+$B$18 | C19: 用于校验执行方式列无缺失/无非法值
A21: 【按模块】
A22: 权限体系
A23: 小计 | B23: =COUNTIF('测试用例'!$B$2:$B$136,"权限体系")
A24: 通过 | B24: =COUNTIFS('测试用例'!$B$2:$B$136,"权限体系",'测试用例'!$K$2:$K$136,"通过")
A25: 失败 | B25: =COUNTIFS('测试用例'!$B$2:$B$136,"权限体系",'测试用例'!$K$2:$K$136,"失败")
A26: 待执行 | B26: =COUNTIFS('测试用例'!$B$2:$B$136,"权限体系",'测试用例'!$K$2:$K$136,"待执行")
A27: 环境受限-范围外 | B27: =COUNTIFS('测试用例'!$B$2:$B$136,"权限体系",'测试用例'!$K$2:$K$136,"环境受限-范围外")
A28: 审批流
A29: 小计 | B29: =COUNTIF('测试用例'!$B$2:$B$136,"审批流")
A30: 通过 | B30: =COUNTIFS('测试用例'!$B$2:$B$136,"审批流",'测试用例'!$K$2:$K$136,"通过")
A31: 失败 | B31: =COUNTIFS('测试用例'!$B$2:$B$136,"审批流",'测试用例'!$K$2:$K$136,"失败")
A32: 待执行 | B32: =COUNTIFS('测试用例'!$B$2:$B$136,"审批流",'测试用例'!$K$2:$K$136,"待执行")
A33: 环境受限-范围外 | B33: =COUNTIFS('测试用例'!$B$2:$B$136,"审批流",'测试用例'!$K$2:$K$136,"环境受限-范围外")
A34: 合同管理
A35: 小计 | B35: =COUNTIF('测试用例'!$B$2:$B$136,"合同管理")
A36: 通过 | B36: =COUNTIFS('测试用例'!$B$2:$B$136,"合同管理",'测试用例'!$K$2:$K$136,"通过")
A37: 失败 | B37: =COUNTIFS('测试用例'!$B$2:$B$136,"合同管理",'测试用例'!$K$2:$K$136,"失败")
A38: 待执行 | B38: =COUNTIFS('测试用例'!$B$2:$B$136,"合同管理",'测试用例'!$K$2:$K$136,"待执行")
A39: 环境受限-范围外 | B39: =COUNTIFS('测试用例'!$B$2:$B$136,"合同管理",'测试用例'!$K$2:$K$136,"环境受限-范围外")
A40: 薪资管理
A41: 小计 | B41: =COUNTIF('测试用例'!$B$2:$B$136,"薪资管理")
A42: 通过 | B42: =COUNTIFS('测试用例'!$B$2:$B$136,"薪资管理",'测试用例'!$K$2:$K$136,"通过")
A43: 失败 | B43: =COUNTIFS('测试用例'!$B$2:$B$136,"薪资管理",'测试用例'!$K$2:$K$136,"失败")
...
